Workbook

Sheet Landing Page
B2: 🚀 RELEASE DESK | D2: Enterprise Release Management Platform | F2: 👤 Welcome, Release Manager | 📅 28/06/2026
B4: 📊 Dashboard | C4: 📋 Releases | D4: 📅 Calendar | E4: ⚠️ Risks | F4: ⚙️ Admin
B6: ⚡ 3 releases scheduled this week | ⚠️ 2 active conflicts require attention | 🔔 5 pending approvals
G7: 📊 QUICK STATS
B8: Welcome to Release Desk
B9: Your central hub for managing releases, tracking risks, coordinating environments, and ensuring successful deployments across the enterprise.
G10: 📋 Total Releases
G11: =COUNTA(Releases!A:A)-1 -> 83
B12: 📱 Main Pages
G13: ⚠️ Active Conflicts
B14: 📊 | D14: 📋 | F14: 📅 | G14: =COUNTIF(Releases!O:O,"*CONFLICT*") -> 27
B15: DASHBOARD | D15: RELEASES | F15: CALENDAR
G16: 🚫 Blocked Releases
B17: Real-time KPIs, metrics, | D17: Manage all releases, | F17: CAB meetings, releases, | G17: =COUNTIF(Releases!N:N,"Blocked") -> 1
B18: and release health overview | D18: status, priorities & blockers | F18: and key milestones
G19: 🔴 P1 Critical
B20: 🖥️ | D20: ⚠️ | F20: 🔗 | G20: =COUNTIF(Releases!H:H,"P1*") -> 11
B21: ENV BOOKING | D21: RISK | F21: DEPENDENCIES
G22: 📝 Pending CAB
B23: Reserve & manage test | D23: Risk scores, factors, | F23: Track inter-release | G23: =COUNTIF(Releases!N:N,"Pending CAB") -> 1
B24: and UAT environments | D24: and mitigation tracking | F24: and system dependencies
G25: ✅ Approved
B26: ✅ | D26: 🏖️ | F26: 📉 | G26: =COUNTIF(Releases!N:N,"Approved") -> 4
B27: APPROVALS | D27: LEAVE CALENDAR | F27: DRIFT
B29: CAB approvals and | D29: Team availability and | F29: Schedule drift analysis
B30: sign-off workflows | D30: resource scheduling | F30: and timeline tracking | G30: ⚡ QUICK ACTIONS
B32: 🔔 Operational Monitoring
G33: ➕ Create New Release
B34: 🔔 | D34: 🚨 | F34: 🖥️
B35: MONITORING | D35: INCIDENTS | F35: APP STATUS | G35: 📅 Book Environment
B37: System alerts, health | D37: P1/P2 incident tracking | F37: Real-time application | G37: 📋 View All Risks
B38: checks & notifications | D38: and resolution status | F38: availability by env
G39: 🔔 Active Alerts
B40: 🔧 | D40: 📦 | F40: 🗺️
B41: MAINTENANCE | D41: VERSIONS | F41: SYSTEM MAPPING | G41: 📊 Open Dashboard
B43: Scheduled outages | D43: Version history and | F43: Environment and system | G43: Last refreshed:
B44: and maintenance windows | D44: deployment tracking | F44: architecture views | G44: =NOW() -> 46203.002
B46: 📚 Reference Data (Admin Only)
B48: 📱 Applications | D48: 👥 Users | F48: ⚙️ Admin Config
B49: Master app registry | D49: User directory | F49: Release Managers & Super Admins
...

Sheet Dashboard
B1: RELEASE DESK DASHBOARD | J1: Last Refresh:
B2: 🔍 FILTERS | C2: Time Period: | D2: This Month | E2: Department: | F2: All | G2: Application: | H2: All | J2: =NOW() -> 46203.002
B4: 📦 RELEASE PIPELINE | E4: ⚠️ RELEASE CONFLICTS & RISKS | H4: 🖥️ ENVIRONMENT BOOKINGS
B5: Total Releases | C5: {=SUMPRODUCT( (Releases!A5:A84<>"")* (IF($D$2="All Time",1,IF($D$2="Today",Releases!J5:J84=TODAY(),IF($D$2="This Week",(Releases!J5:J84>=TODAY())*(Releases!J5:J84<=TODAY()+7),IF($D$2="This Month",(Releases!J5:J84>=TODAY())*(Releases!J5:J84<=TODAY()+30),(Releases!J5:J84>=DATE(YEAR(TODAY()),1,1))*(Releases!J5:J84<=DATE(YEAR(TODAY()),12,31)))))))* (IF($F$2="All",1,Releases!C5:C84=$F$2))* (IF($H$2="All",1,Releases!D5:D84=$H$2)) )} -> 9 | E5: Active Conflicts | F5: {=SUMPRODUCT( (ISNUMBER(SEARCH("CONFLICT",Releases!O5:O84)))* (IF($D$2="All Time",1,IF($D$2="Today",Releases!J5:J84=TODAY(),IF($D$2="This Week",(Releases!J5:J84>=TODAY())*(Releases!J5:J84<=TODAY()+7),IF($D$2="This Month",(Releases!J5:J84>=TODAY())*(Releases!J5:J84<=TODAY()+30),(Releases!J5:J84>=DATE(YEAR(TODAY()),1,1))*(Releases!J5:J84<=DATE(YEAR(TODAY()),12,31)))))))* (IF($F$2="All",1,Releases!C5:C84=$F$2))* (IF($H$2="All",1,Releases!D5:D84=$H$2)) )} -> 6 | H5: Env Conflicts | I5: {=SUMPRODUCT( (ISNUMBER(SEARCH("CONFLICT",'Env booking'!U5:U115)))* (IF($F$2="All",1,'Env booking'!D5:D115=$F$2)) )} -> 26
B6: Blocked | C6: {=SUMPRODUCT( (Releases!N5:N84="Blocked")* (IF($D$2="All Time",1,IF($D$2="Today",Releases!J5:J84=TODAY(),IF($D$2="This Week",(Releases!J5:J84>=TODAY())*(Releases!J5:J84<=TODAY()+7),IF($D$2="This Month",(Releases!J5:J84>=TODAY())*(Releases!J5:J84<=TODAY()+30),(Releases!J5:J84>=DATE(YEAR(TODAY()),1,1))*(Releases!J5:J84<=DATE(YEAR(TODAY()),12,31)))))))* (IF($F$2="All",1,Releases!C5:C84=$F$2))* (IF($H$2="All",1,Releases!D5:D84=$H$2)) )} -> 1 | E6: Critical Risk (Score 20+) | F6: {=SUMPRODUCT( (Risk!J5:J81>=20)* (IF($F$2="All",1,Risk!C5:C81=$F$2)) )} -> 2 | H6: Env Bookings Active | I6: {=SUMPRODUCT( ('Env booking'!A5:A115<>"")* (IF($F$2="All",1,'Env booking'!D5:D115=$F$2)) )} -> 101
B7: Approved | C7: {=SUMPRODUCT( (Releases!N5:N84="Approved")* (IF($D$2="All Time",1,IF($D$2="Today",Releases!J5:J84=TODAY(),IF($D$2="This Week",(Releases!J5:J84>=TODAY())*(Releases!J5:J84<=TODAY()+7),IF($D$2="This Month",(Releases!J5:J84>=TODAY())*(Releases!J5:J84<=TODAY()+30),(Releases!J5:J84>=DATE(YEAR(TODAY()),1,1))*(Releases!J5:J84<=DATE(YEAR(TODAY()),12,31)))))))* (IF($F$2="All",1,Releases!C5:C84=$F$2))* (IF($H$2="All",1,Releases!D5:D84=$H$2)) )} -> 4 | E7: High Risk (Score 15-19) | F7: {=SUMPRODUCT( (Risk!J5:J81>=15)*(Risk!J5:J81<20)* (IF($F$2="All",1,Risk!C5:C81=$F$2)) )} -> 3
B8: Testing | C8: {=SUMPRODUCT( (Releases!N5:N84="Testing")* (IF($D$2="All Time",1,IF($D$2="Today",Releases!J5:J84=TODAY(),IF($D$2="This Week",(Releases!J5:J84>=TODAY())*(Releases!J5:J84<=TODAY()+7),IF($D$2="This Month",(Releases!J5:J84>=TODAY())*(Releases!J5:J84<=TODAY()+30),(Releases!J5:J84>=DATE(YEAR(TODAY()),1,1))*(Releases!J5:J84<=DATE(YEAR(TODAY()),12,31)))))))* (IF($F$2="All",1,Releases!C5:C84=$F$2))* (IF($H$2="All",1,Releases!D5:D84=$H$2)) )} -> 3 | E8: Medium Risk (Score 10-14) | F8: {=SUMPRODUCT( (Risk!J5:J81>=10)*(Risk!J5:J81<15)* (IF($F$2="All",1,Risk!C5:C81=$F$2)) )} -> 12 | H8: 🔗 DEPENDENCIES
B9: Planning | C9: {=SUMPRODUCT( (Releases!N5:N84="Planning")* (IF($D$2="All Time",1,IF($D$2="Today",Releases!J5:J84=TODAY(),IF($D$2="This Week",(Releases!J5:J84>=TODAY())*(Releases!J5:J84<=TODAY()+7),IF($D$2="This Month",(Releases!J5:J84>=TODAY())*(Releases!J5:J84<=TODAY()+30),(Releases!J5:J84>=DATE(YEAR(TODAY()),1,1))*(Releases!J5:J84<=DATE(YEAR(TODAY()),12,31)))))))* (IF($F$2="All",1,Releases!C5:C84=$F$2))* (IF($H$2="All",1,Releases!D5:D84=$H$2)) )} -> 0 | E9: Low Risk (Score <10) | F9: {=SUMPRODUCT( (Risk!J5:J81>0)*(Risk!J5:J81<10)* (IF($F$2="All",1,Risk!C5:C81=$F$2)) )} -> 14 | H9: Blocked Dependencies | I9: {=SUMPRODUCT( (Dependencies!G4:G91="Blocked")* (IF($F$2="All",1,Dependencies!#REF!=$F$2)) )} -> 5
B10: Draft | C10: {=SUMPRODUCT( (Releases!N5:N84="Draft")* (IF($D$2="All Time",1,IF($D$2="Today",Releases!J5:J84=TODAY(),IF($D$2="This Week",(Releases!J5:J84>=TODAY())*(Releases!J5:J84<=TODAY()+7),IF($D$2="This Month",(Releases!J5:J84>=TODAY())*(Releases!J5:J84<=TODAY()+30),(Releases!J5:J84>=DATE(YEAR(TODAY()),1,1))*(Releases!J5:J84<=DATE(YEAR(TODAY()),12,31)))))))* (IF($F$2="All",1,Releases!C5:C84=$F$2))* (IF($H$2="All",1,Releases!D5:D84=$H$2)) )} -> 0 | H10: Total Dependencies | I10: {=SUMPRODUCT( (Dependencies!A4:A91<>"")* (IF($F$2="All",1,Dependencies!#REF!=$F$2)) )} -> 69
B11: Pending CAB | C11: {=SUMPRODUCT( (Releases!N5:N84="Pending CAB")* (IF($D$2="All Time",1,IF($D$2="Today",Releases!J5:J84=TODAY(),IF($D$2="This Week",(Releases!J5:J84>=TODAY())*(Releases!J5:J84<=TODAY()+7),IF($D$2="This Month",(Releases!J5:J84>=TODAY())*(Releases!J5:J84<=TODAY()+30),(Releases!J5:J84>=DATE(YEAR(TODAY()),1,1))*(Releases!J5:J84<=DATE(YEAR(TODAY()),12,31)))))))* (IF($F$2="All",1,Releases!C5:C84=$F$2))* (IF($H$2="All",1,Releases!D5:D84=$H$2)) )} -> 1 | E11: 📋 CAB & APPROVALS
B12: P1 - Critical | C12: {=SUMPRODUCT( (Releases!H5:H84="P1 - Critical")* (IF($D$2="All Time",1,IF($D$2="Today",Releases!J5:J84=TODAY(),IF($D$2="This Week",(Releases!J5:J84>=TODAY())*(Releases!J5:J84<=TODAY()+7),IF($D$2="This Month",(Releases!J5:J84>=TODAY())*(Releases!J5:J84<=TODAY()+30),(Releases!J5:J84>=DATE(YEAR(TODAY()),1,1))*(Releases!J5:J84<=DATE(YEAR(TODAY()),12,31)))))))* (IF($F$2="All",1,Releases!C5:C84=$F$2))* (IF($H$2="All",1,Releases!D5:D84=$H$2)) )} -> 2 | E12: CAB Meetings (Next 7 Days) | F12: {=SUMPRODUCT( (Calendar!E15:E180="CAB MEETING")* (IF($D$2="All Time",1,IF($D$2="Today",Calendar!C15:C180=TODAY(),IF($D$2="This Week",(Calendar!C15:C180>=TODAY())*(Calendar!C15:C180<=TODAY()+7),IF($D$2="This Month",(Calendar!C15:C180>=TODAY())*(Calendar!C15:C180<=TODAY()+30),(Calendar!C15:C180>=DATE(YEAR(TODAY()),1,1))*(Calendar!C15:C180<=DATE(YEAR(TODAY()),12,31))))))) )} -> 9 | H12: 👥 RESOURCE AVAILABILITY
B13: P2 - High | C13: {=SUMPRODUCT( (Releases!H5:H84="P2 - High")* (IF($D$2="All Time",1,IF($D$2="Today",Releases!J5:J84=TODAY(),IF($D$2="This Week",(Releases!J5:J84>=TODAY())*(Releases!J5:J84<=TODAY()+7),IF($D$2="This Month",(Releases!J5:J84>=TODAY())*(Releases!J5:J84<=TODAY()+30),(Releases!J5:J84>=DATE(YEAR(TODAY()),1,1))*(Releases!J5:J84<=DATE(YEAR(TODAY()),12,31)))))))* (IF($F$2="All",1,Releases!C5:C84=$F$2))* (IF($H$2="All",1,Releases!D5:D84=$H$2)) )} -> 4 | E13: Pending Approvals | F13: {=SUMPRODUCT( ((Releases!W5:W84="CAB Submitted")+(Releases!W5:W84="On Hold"))* (IF($D$2="All Time",1,IF($D$2="Today",Releases!J5:J84=TODAY(),IF($D$2="This Week",(Releases!J5:J84>=TODAY())*(Releases!J5:J84<=TODAY()+7),IF($D$2="This Month",(Releases!J5:J84>=TODAY())*(Releases!J5:J84<=TODAY()+30),(Releases!J5:J84>=DATE(YEAR(TODAY()),1,1))*(Releases!J5:J84<=DATE(YEAR(TODAY()),12,31)))))))* (IF($F$2="All",1,Releases!C5:C84=$F$2))* (IF($H$2="All",1,Releases!D5:D84=$H$2)) )} -> 2 | H13: Staff on Leave Today | I13: =COUNTIFS('Leave Calendar'!F4:F93,"<="&TODAY(),'Leave Calendar'!G4:G93,">="&TODAY()) -> 1
B14: P3 - Medium | C14: {=SUMPRODUCT( (Releases!H5:H84="P3 - Medium")* (IF($D$2="All Time",1,IF($D$2="Today",Releases!J5:J84=TODAY(),IF($D$2="This Week",(Releases!J5:J84>=TODAY())*(Releases!J5:J84<=TODAY()+7),IF($D$2="This Month",(Releases!J5:J84>=TODAY())*(Releases!J5:J84<=TODAY()+30),(Releases!J5:J84>=DATE(YEAR(TODAY()),1,1))*(Releases!J5:J84<=DATE(YEAR(TODAY()),12,31)))))))* (IF($F$2="All",1,Releases!C5:C84=$F$2))* (IF($H$2="All",1,Releases!D5:D84=$H$2)) )} -> 2 | H14: Staff on Leave (7 Days) | I14: {=SUMPRODUCT( ('Leave Calendar'!F4:F93<=TODAY()+IF($D$2="Today",0,IF($D$2="This Week",7,IF($D$2="This Month",30,365))))* ('Leave Calendar'!G4:G93>=TODAY()) )} -> 4
B15: P4 - Low | C15: {=SUMPRODUCT( (Releases!H5:H84="P4 - Low")* (IF($D$2="All Time",1,IF($D$2="Today",Releases!J5:J84=TODAY(),IF($D$2="This Week",(Releases!J5:J84>=TODAY())*(Releases!J5:J84<=TODAY()+7),IF($D$2="This Month",(Releases!J5:J84>=TODAY())*(Releases!J5:J84<=TODAY()+30),(Releases!J5:J84>=DATE(YEAR(TODAY()),1,1))*(Releases!J5:J84<=DATE(YEAR(TODAY()),12,31)))))))* (IF($F$2="All",1,Releases!C5:C84=$F$2))* (IF($H$2="All",1,Releases!D5:D84=$H$2)) )} -> 1
B17: 🚨 MONITORING ALERTS | E17: 🔥 INCIDENTS | H17: 📊 APPLICATION AVAILABILITY
B18: Critical Alerts (Active) | C18: {=SUMPRODUCT( ('Monitoring Alerts'!F:F="Critical")* ('Monitoring Alerts'!J:J="Active")* (IF($D$2="All Time",1,IF($D$2="Today",'Monitoring Alerts'!B:B>=TODAY(),IF($D$2="This Week",('Monitoring Alerts'!B:B>=TODAY()-7),IF($D$2="This Month",('Monitoring Alerts'!B:B>=TODAY()-30),('Monitoring Alerts'!B:B>=DATE(YEAR(TODAY()),1,1)))))))* (IF($F$2="All",1,'Monitoring Alerts'!D:D=$F$2))* (IF($H$2="All",1,'Monitoring Alerts'!C:C=$H$2)) )} -> 11 | E18: P1 Incidents (Active) | F18: {=SUMPRODUCT( (Incidents!E:E="P1")* (Incidents!G:G<>"Resolved")* (IF($D$2="All Time",1,IF($D$2="Today",Incidents!B:B>=TODAY(),IF($D$2="This Week",(Incidents!B:B>=TODAY()-7),IF($D$2="This Month",(Incidents!B:B>=TODAY()-30),(Incidents!B:B>=DATE(YEAR(TODAY()),1,1)))))))* (IF($F$2="All",1,Incidents!D:D=$F$2))* (IF($H$2="All",1,Incidents!C:C=$H$2)) )} -> 4 | H18: Apps Down - Production | I18: {=SUMPRODUCT( ('Application Status'!C:C="Prod")* ('Application Status'!D:D="Down")* (IF($F$2="All",1,'Application Status'!B:B=$F$2))* (IF($H$2="All",1,'Application Status'!A:A=$H$2)) )} -> 4
B19: Warning Alerts (Active) | C19: {=SUMPRODUCT( ('Monitoring Alerts'!F:F="Warning")* ('Monitoring Alerts'!J:J="Active")* (IF($D$2="All Time",1,IF($D$2="Today",'Monitoring Alerts'!B:B>=TODAY(),IF($D$2="This Week",('Monitoring Alerts'!B:B>=TODAY()-7),IF($D$2="This Month",('Monitoring Alerts'!B:B>=TODAY()-30),('Monitoring Alerts'!B:B>=DATE(YEAR(TODAY()),1,1)))))))* (IF($F$2="All",1,'Monitoring Alerts'!D:D=$F$2))* (IF($H$2="All",1,'Monitoring Alerts'!C:C=$H$2)) )} -> 16 | E19: P2 Incidents (Active) | F19: {=SUMPRODUCT( (Incidents!E:E="P2")* (Incidents!G:G<>"Resolved")* (IF($D$2="All Time",1,IF($D$2="Today",Incidents!B:B>=TODAY(),IF($D$2="This Week",(Incidents!B:B>=TODAY()-7),IF($D$2="This Month",(Incidents!B:B>=TODAY()-30),(Incidents!B:B>=DATE(YEAR(TODAY()),1,1)))))))* (IF($F$2="All",1,Incidents!D:D=$F$2))* (IF($H$2="All",1,Incidents!C:C=$H$2)) )} -> 6 | H19: Apps Degraded - Production | I19: {=SUMPRODUCT( ('Application Status'!C:C="Prod")* ('Application Status'!D:D="Degraded")* (IF($F$2="All",1,'Application Status'!B:B=$F$2))* (IF($H$2="All",1,'Application Status'!A:A=$H$2)) )} -> 5
B20: Info Alerts (Active) | C20: {=SUMPRODUCT( ('Monitoring Alerts'!F:F="Info")* ('Monitoring Alerts'!J:J="Active")* (IF($D$2="All Time",1,IF($D$2="Today",'Monitoring Alerts'!B:B>=TODAY(),IF($D$2="This Week",('Monitoring Alerts'!B:B>=TODAY()-7),IF($D$2="This Month",('Monitoring Alerts'!B:B>=TODAY()-30),('Monitoring Alerts'!B:B>=DATE(YEAR(TODAY()),1,1)))))))* (IF($F$2="All",1,'Monitoring Alerts'!D:D=$F$2))* (IF($H$2="All",1,'Monitoring Alerts'!C:C=$H$2)) )} -> 2 | E20: P3 Incidents (Active) | F20: {=SUMPRODUCT( (Incidents!E:E="P3")* (Incidents!G:G<>"Resolved")* (IF($D$2="All Time",1,IF($D$2="Today",Incidents!B:B>=TODAY(),IF($D$2="This Week",(Incidents!B:B>=TODAY()-7),IF($D$2="This Month",(Incidents!B:B>=TODAY()-30),(Incidents!B:B>=DATE(YEAR(TODAY()),1,1)))))))* (IF($F$2="All",1,Incidents!D:D=$F$2))* (IF($H$2="All",1,Incidents!C:C=$H$2)) )} -> 3 | H20: Apps Healthy - Production | I20: {=SUMPRODUCT( ('Application Status'!C:C="Prod")* ('Application Status'!D:D="Healthy")* (IF($F$2="All",1,'Application Status'!B:B=$F$2))* (IF($H$2="All",1,'Application Status'!A:A=$H$2)) )} -> 11
B21: Acknowledged | C21: {=SUMPRODUCT( ('Monitoring Alerts'!J:J="Acknowledged")* (IF($D$2="All Time",1,IF($D$2="Today",'Monitoring Alerts'!B:B>=TODAY(),IF($D$2="This Week",('Monitoring Alerts'!B:B>=TODAY()-7),IF($D$2="This Month",('Monitoring Alerts'!B:B>=TODAY()-30),('Monitoring Alerts'!B:B>=DATE(YEAR(TODAY()),1,1)))))))* (IF($F$2="All",1,'Monitoring Alerts'!D:D=$F$2))* (IF($H$2="All",1,'Monitoring Alerts'!C:C=$H$2)) )} -> 5 | E21: Investigating | F21: {=SUMPRODUCT( (Incidents!G:G="Investigating")* (IF($D$2="All Time",1,IF($D$2="Today",Incidents!B:B>=TODAY(),IF($D$2="This Week",(Incidents!B:B>=TODAY()-7),IF($D$2="This Month",(Incidents!B:B>=TODAY()-30),(Incidents!B:B>=DATE(YEAR(TODAY()),1,1)))))))* (IF($F$2="All",1,Incidents!D:D=$F$2))* (IF($H$2="All",1,Incidents!C:C=$H$2)) )} -> 4 | H21: Apps Down - Lower Env | I21: {=SUMPRODUCT( ('Application Status'!C:C<>"Prod")* ('Application Status'!D:D="Down")* ('Application Status'!A:A<>"")* (IF($F$2="All",1,'Application Status'!B:B=$F$2))* (IF($H$2="All",1,'Application Status'!A:A=$H$2)) )} -> 5
B22: Resolved (Last 24h) | C22: {=SUMPRODUCT( ('Monitoring Alerts'!J:J="Resolved")* ('Monitoring Alerts'!B:B>=TODAY()-1)* (IF($F$2="All",1,'Monitoring Alerts'!D:D=$F$2))* (IF($H$2="All",1,'Monitoring Alerts'!C:C=$H$2)) )} -> 0 | E22: Resolved (Last 24h) | F22: {=SUMPRODUCT( (Incidents!G:G="Resolved")* (Incidents!B:B>=TODAY()-1)* (IF($F$2="All",1,Incidents!D:D=$F$2))* (IF($H$2="All",1,Incidents!C:C=$H$2)) )} -> 0 | H22: Apps Degraded - Lower Env | I22: {=SUMPRODUCT( ('Application Status'!C:C<>"Prod")* ('Application Status'!D:D="Degraded")* ('Application Status'!A:A<>"")* (IF($F$2="All",1,'Application Status'!B:B=$F$2))* (IF($H$2="All",1,'Application Status'!A:A=$H$2)) )} -> 3
B23: Total Active Alerts | C23: {=SUMPRODUCT( (('Monitoring Alerts'!J:J="Active")+('Monitoring Alerts'!J:J="Acknowledged"))* (IF($D$2="All Time",1,IF($D$2="Today",'Monitoring Alerts'!B:B>=TODAY(),IF($D$2="This Week",('Monitoring Alerts'!B:B>=TODAY()-7),IF($D$2="This Month",('Monitoring Alerts'!B:B>=TODAY()-30),('Monitoring Alerts'!B:B>=DATE(YEAR(TODAY()),1,1)))))))* (IF($F$2="All",1,'Monitoring Alerts'!D:D=$F$2))* (IF($H$2="All",1,'Monitoring Alerts'!C:C=$H$2)) )} -> 34 | E23: Total Active Incidents | F23: {=SUMPRODUCT( ((Incidents!G:G="Active")+(Incidents!G:G="Investigating")+(Incidents!G:G="Acknowledged"))* (IF($D$2="All Time",1,IF($D$2="Today",Incidents!B:B>=TODAY(),IF($D$2="This Week",(Incidents!B:B>=TODAY()-7),IF($D$2="This Month",(Incidents!B:B>=TODAY()-30),(Incidents!B:B>=DATE(YEAR(TODAY()),1,1)))))))* (IF($F$2="All",1,Incidents!D:D=$F$2))* (IF($H$2="All",1,Incidents!C:C=$H$2)) )} -> 13 | H23: Total App-Env Records | I23: {=SUMPRODUCT( ('Application Status'!A:A<>"")* ('Application Status'!A:A<>"Application")* (IF($F$2="All",1,'Application Status'!B:B=$F$2))* (IF($H$2="All",1,'Application Status'!A:A=$H$2)) )} -> 85
B26: 🔧 PLANNED MAINTENANCE | E26: ❄️ CHANGE FREEZE | H26: 📈 QUICK STATS
B27: Scheduled Today | C27: {=SUMPRODUCT( ('Planned Maintenance'!B:B=TODAY())* (IF($F$2="All",1,'Planned Maintenance'!H:H=$F$2)) )} -> 2 | E27: Quarter-End Freeze | F27: {=SUMPRODUCT( (ISNUMBER(SEARCH("Quarter",Releases!T5:T84)))* (IF($D$2="All Time",1,IF($D$2="Today",Releases!J5:J84=TODAY(),IF($D$2="This Week",(Releases!J5:J84>=TODAY())*(Releases!J5:J84<=TODAY()+7),IF($D$2="This Month",(Releases!J5:J84>=TODAY())*(Releases!J5:J84<=TODAY()+30),(Releases!J5:J84>=DATE(YEAR(TODAY()),1,1))*(Releases!J5:J84<=DATE(YEAR(TODAY()),12,31)))))))* (IF($F$2="All",1,Releases!C5:C84=$F$2))* (IF($H$2="All",1,Releases!D5:D84=$H$2)) )} -> 1 | H27: Releases This Week | I27: {=SUMPRODUCT( (Releases!A5:A84<>"")* (Releases!J5:J84>=TODAY())* (Releases!J5:J84<=TODAY()+7)* (IF($F$2="All",1,Releases!C5:C84=$F$2))* (IF($H$2="All",1,Releases!D5:D84=$H$2)) )} -> 5
B28: ="DB Refreshes ("&IF($D$2="Today","Today",IF($D$2="This Week","7 Days",IF($D$2="This Month","30 Days",IF($D$2="This Year","Year","All"))))&")" -> DB Refreshes (30 Days) | C28: {=SUMPRODUCT( ('Planned Maintenance'!E:E="DB Refresh")* ('Planned Maintenance'!B:B>=TODAY())* ('Planned Maintenance'!B:B<=TODAY()+IF($D$2="Today",0,IF($D$2="This Week",7,IF($D$2="This Month",30,365))))* (IF($F$2="All",1,'Planned Maintenance'!H:H=$F$2)) )} -> 4 | E28: Year-End Freeze | F28: {=SUMPRODUCT( (ISNUMBER(SEARCH("Year",Releases!T5:T84)))* (IF($D$2="All Time",1,IF($D$2="Today",Releases!J5:J84=TODAY(),IF($D$2="This Week",(Releases!J5:J84>=TODAY())*(Releases!J5:J84<=TODAY()+7),IF($D$2="This Month",(Releases!J5:J84>=TODAY())*(Releases!J5:J84<=TODAY()+30),(Releases!J5:J84>=DATE(YEAR(TODAY()),1,1))*(Releases!J5:J84<=DATE(YEAR(TODAY()),12,31)))))))* (IF($F$2="All",1,Releases!C5:C84=$F$2))* (IF($H$2="All",1,Releases!D5:D84=$H$2)) )} -> 0 | H28: Releases This Month | I28: {=SUMPRODUCT( (Releases!A5:A84<>"")* (Releases!J5:J84>=TODAY())* (Releases!J5:J84<=TODAY()+30)* (IF($F$2="All",1,Releases!C5:C84=$F$2))* (IF($H$2="All",1,Releases!D5:D84=$H$2)) )} -> 9
B29: ="Vendor Windows ("&IF($D$2="Today","Today",IF($D$2="This Week","7 Days",IF($D$2="This Month","30 Days",IF($D$2="This Year","Year","All"))))&")" -> Vendor Windows (30 Days) | C29: {=SUMPRODUCT( ('Planned Maintenance'!E:E="Vendor Maintenance")* ('Planned Maintenance'!B:B>=TODAY())* ('Planned Maintenance'!B:B<=TODAY()+IF($D$2="Today",0,IF($D$2="This Week",7,IF($D$2="This Month",30,365))))* (IF($F$2="All",1,'Planned Maintenance'!H:H=$F$2)) )} -> 4 | E29: Audit Freeze | F29: {=SUMPRODUCT( (ISNUMBER(SEARCH("Audit",Releases!T5:T84)))* (IF($D$2="All Time",1,IF($D$2="Today",Releases!J5:J84=TODAY(),IF($D$2="This Week",(Releases!J5:J84>=TODAY())*(Releases!J5:J84<=TODAY()+7),IF($D$2="This Month",(Releases!J5:J84>=TODAY())*(Releases!J5:J84<=TODAY()+30),(Releases!J5:J84>=DATE(YEAR(TODAY()),1,1))*(Releases!J5:J84<=DATE(YEAR(TODAY()),12,31)))))))* (IF($F$2="All",1,Releases!C5:C84=$F$2))* (IF($H$2="All",1,Releases!D5:D84=$H$2)) )} -> 0 | H29: With Rollback Plan Ready | I29: {=SUMPRODUCT( (Releases!Y5:Y84="Ready")* (IF($D$2="All Time",1,IF($D$2="Today",Releases!J5:J84=TODAY(),IF($D$2="This Week",(Releases!J5:J84>=TODAY())*(Releases!J5:J84<=TODAY()+7),IF($D$2="This Month",(Releases!J5:J84>=TODAY())*(Releases!J5:J84<=TODAY()+30),(Releases!J5:J84>=DATE(YEAR(TODAY()),1,1))*(Releases!J5:J84<=DATE(YEAR(TODAY()),12,31)))))))* (IF($F$2="All",1,Releases!C5:C84=$F$2))* (IF($H$2="All",1,Releases!D5:D84=$H$2)) )} -> 4
B30: ="Full Outages ("&IF($D$2="Today","Today",IF($D$2="This Week","7 Days",IF($D$2="This Month","30 Days",IF($D$2="This Year","Year","All"))))&")" -> Full Outages (30 Days) | C30: {=SUMPRODUCT( ('Planned Maintenance'!I:I="Full Outage")* ('Planned Maintenance'!B:B>=TODAY())* ('Planned Maintenance'!B:B<=TODAY()+IF($D$2="Today",0,IF($D$2="This Week",7,IF($D$2="This Month",30,365))))* (IF($F$2="All",1,'Planned Maintenance'!H:H=$F$2)) )} -> 7 | E30: Holiday Freeze | F30: {=SUMPRODUCT( (ISNUMBER(SEARCH("Holiday",Releases!T5:T84)))* (IF($D$2="All Time",1,IF($D$2="Today",Releases!J5:J84=TODAY(),IF($D$2="This Week",(Releases!J5:J84>=TODAY())*(Releases!J5:J84<=TODAY()+7),IF($D$2="This Month",(Releases!J5:J84>=TODAY())*(Releases!J5:J84<=TODAY()+30),(Releases!J5:J84>=DATE(YEAR(TODAY()),1,1))*(Releases!J5:J84<=DATE(YEAR(TODAY()),12,31)))))))* (IF($F$2="All",1,Releases!C5:C84=$F$2))* (IF($H$2="All",1,Releases!D5:D84=$H$2)) )} -> 0 | H30: Rollback At Risk | I30: {=SUMPRODUCT( (Releases!Y5:Y84="At Risk")* (IF($D$2="All Time",1,IF($D$2="Today",Releases!J5:J84=TODAY(),IF($D$2="This Week",(Releases!J5:J84>=TODAY())*(Releases!J5:J84<=TODAY()+7),IF($D$2="This Month",(Releases!J5:J84>=TODAY())*(Releases!J5:J84<=TODAY()+30),(Releases!J5:J84>=DATE(YEAR(TODAY()),1,1))*(Releases!J5:J84<=DATE(YEAR(TODAY()),12,31)))))))* (IF($F$2="All",1,Releases!C5:C84=$F$2))* (IF($H$2="All",1,Releases!D5:D84=$H$2)) )} -> 1
B31: ="Total Maintenance ("&IF($D$2="Today","Today",IF($D$2="This Week","7 Days",IF($D$2="This Month","30 Days",IF($D$2="This Year","Year","All"))))&")" -> Total Maintenance (30 Days) | C31: {=SUMPRODUCT( ('Planned Maintenance'!A:A<>"")* ('Planned Maintenance'!A:A<>"Maintenance ID")* ('Planned Maintenance'!B:B>=TODAY())* ('Planned Maintenance'!B:B<=TODAY()+IF($D$2="Today",0,IF($D$2="This Week",7,IF($D$2="This Month",30,365))))* (IF($F$2="All",1,'Planned Maintenance'!H:H=$F$2)) )} -> 15 | E31: Total Frozen Releases | F31: {=SUMPRODUCT( (Releases!T5:T84<>"")* (IF($D$2="All Time",1,IF($D$2="Today",Releases!J5:J84=TODAY(),IF($D$2="This Week",(Releases!J5:J84>=TODAY())*(Releases!J5:J84<=TODAY()+7),IF($D$2="This Month",(Releases!J5:J84>=TODAY())*(Releases!J5:J84<=TODAY()+30),(Releases!J5:J84>=DATE(YEAR(TODAY()),1,1))*(Releases!J5:J84<=DATE(YEAR(TODAY()),12,31)))))))* (IF($F$2="All",1,Releases!C5:C84=$F$2))* (IF($H$2="All",1,Releases!D5:D84=$H$2)) )} -> 1 | H31: Avg Go-Live Checklist % | I31: =IFERROR(TEXT(AVERAGEIF(Releases!Z5:Z84,"<>",Releases!Z5:Z84),"0%"),"N/A") -> 18%
B35: 🚦 OVERALL HEALTH STATUS
B36: Release Pipeline | D36: Environment Health | F36: Incident Status | H36: Alert Status
B37: =IF(C6>2,"🔴 Critical",IF(C6>=1,"🟡 Warning","🟢 Healthy")) -> 🟡 Warning | D37: =IF(I18>2,"🔴 Critical",IF(I18>=1,"🟡 Warning","🟢 Healthy")) -> 🔴 Critical | F37: =IF(F18>2,"🔴 Critical",IF(F18>=1,"🟡 Warning","🟢 Healthy")) -> 🔴 Critical | H37: =IF(C18>5,"🔴 Critical",IF(C18>=1,"🟡 Warning","🟢 Healthy")) -> 🔴 Critical
B39: 📊 SUMMARY TOTALS
B40: Total Releases | C40: =C5 -> 9 | D40: Active Incidents | E40: =F23 -> 13 | F40: Active Alerts | G40: =C23 -> 34 | H40: Apps Down | I40: =I18+I21 -> 9
B42: 📈 RELEASE TREND (Next 4 Weeks)
B43: Week 1 | C43: Week 2 | D43: Week 3 | E43: Week 4 | F43: Trend
A44: Releases | B44: {=SUMPRODUCT((Releases!J5:J84>=TODAY())*(Releases!J5:J84<TODAY()+7)*(IF($F$2="All",1,Releases!C5:C84=$F$2))*(IF($H$2="All",1,Releases!D5:D84=$H$2)))} -> 5 | C44: {=SUMPRODUCT((Releases!J5:J84>=TODAY()+7)*(Releases!J5:J84<TODAY()+14)*(IF($F$2="All",1,Releases!C5:C84=$F$2))*(IF($H$2="All",1,Releases!D5:D84=$H$2)))} -> 1 | D44: {=SUMPRODUCT((Releases!J5:J84>=TODAY()+14)*(Releases!J5:J84<TODAY()+21)*(IF($F$2="All",1,Releases!C5:C84=$F$2))*(IF($H$2="All",1,Releases!D5:D84=$H$2)))} -> 3 | E44: {=SUMPRODUCT((Releases!J5:J84>=TODAY()+21)*(Releases!J5:J84<TODAY()+28)*(IF($F$2="All",1,Releases!C5:C84=$F$2))*(IF($H$2="All",1,Releases!D5:D84=$H$2)))} -> 0 | F44: =IF(E44>B44,"📈 ↑ Increasing",IF(E44<B44,"📉 ↓ Decreasing","➡️ Stable")) -> 📉 ↓ Decreasing
B45: =REPT("█",B44) -> █████ | C45: =REPT("█",C44) -> █ | D45: =REPT("█",D44) -> ███ | E45: =REPT("█",E44)
A46: Incidents | B46: P1 | C46: P2 | D46: P3 | E46: Total | F46: Trend
B47: =F18 -> 4 | C47: =F19 -> 6 | D47: =F20 -> 3 | E47: =F23 -> 13 | F47: =IF(F18>0,"🔴 P1 Active!",IF(F19>2,"🟠 Watch P2","🟢 Stable")) -> 🔴 P1 Active!

Sheet README
A1: ═══════════════════════════════════════════════════════════════════════════════════════════════════════════════════
A2: RELEASEDESK - SAMPLE DATA SPECIFICATION FOR PROTOTYPE BUILDER
A3: ═══════════════════════════════════════════════════════════════════════════════════════════════════════════════════
A5: DOCUMENT PURPOSE
A6: This workbook provides structured sample/seed data for a Release Management System prototype.
A7: It is designed to be parsed and interpreted by an AI/Machine that generates wireframes and UI prototypes.
A8: Each sheet represents a distinct data entity with defined schemas, relationships, and business rules.
A10: HOW TO USE THIS DOCUMENT
A11: 1. Start with this README to understand the data model and relationships
A12: 2. Reference the 'Reference Data' sheet for all lookup values, status codes, and enumeration tables
A13: 3. Each data sheet has a defined schema (column headers in Row 1 or as specified)
A14: 4. Foreign keys (FK) link entities - always validate relationships exist
... A26: ENTITY COUNTS (for prototype sizing)
A27: Entity | B27: Count | C27: Primary Key | D27: Source Sheet
A28: Departments | B28: 8 | C28: DEPT-## | D28: Reference Data (Row 40)
A29: Applications | B29: 84 | C29: Composite (Dept+App) | D29: Applications
A30: Environment Instances | B30: 504 | C30: Composite (App+Env) | D30: Applications (84 apps × 6 envs)
A31: Users | B31: 100 | C31: USR-### | D31: Users
A32: Release Managers | B32: 12 | C32: RM-### | D32: Admin (Release Managers)
A33: Super Admins | B33: 12 | C33: SA-### | D33: Super Admins
A34: Releases | B34: 80 | C34: REL-#### | D34: Releases
A35: Environment Bookings | B35: 80+ | C35: ENV-#### | D35: Env booking
A36: Calendar Events | B36: 166 | C36: Row-based | D36: Calendar
A37: Risk Records | B37: 31 | C37: RSK-### | D37: Risk
A38: Drift Issues | B38: 7 | C38: DFT-### | D38: Drift
A39: Dependencies | B39: 26 | C39: DEP-### | D39: Dependencies
A40: Approvals | B40: 27 | C40: APR-### | D40: Approvals
A41: Leave Records | B41: 30 | C41: LV-### | D41: Leave Calendar
A42: Version Records | B42: 180 | C42: APP-### | D42: Versions
A43: Risk Factors | B43: 44-46 | C43: Category+Factor | D43: Risk Factors
A45: TIME SPAN
A46: Release Calendar Period: July 2026 - June 2027 (12 months)
A47: Simulated 'Today' Date: June 25, 2026
A49: KEY METRICS FOR PROTOTYPE
A50: Conflict Rate: ~32% (26 releases have resource conflicts)
A51: Environments per Application: 6 (Dev, Test, UAT, Pre-prod, Prod, DR)
A52: Average Releases per Month: 6-7
A53: Risk Score Range: 1-25 (Likelihood × Impact)
A55: ═══════════════════════════════════════════════════════════════════════════════════════════════════════════════════
A56: SECTION 2: SHEET INVENTORY & NAVIGATION
...

Sheet Technical Specifications
A1: TECHNICAL SPECIFICATIONS - Release Desk Data Dictionary
A3: PURPOSE OF THIS DOCUMENT
A4: ═══════════════════════════════════════════════════════════════════════════════════════════════════════════════════════════════════════════
A6: This sheet contains technical specifications for developers building the Release Desk application.
A8: CONTENTS:
A9: • Data types, Primary Keys (PK), and Foreign Keys (FK) for each table/sheet
A10: • Entity relationship diagrams showing how data connects
A11: • Validation rules and integrity constraints
A12: • Cardinality (1:1, 1:M, M:M relationships)
A14: WHO SHOULD USE THIS:
A15: • Backend developers implementing the database schema
A16: • API developers creating endpoints
... A68: FOREIGN KEY REFERENCE TABLE
A70: Source Sheet | B70: FK Column | C70: → | D70: Target Sheet | E70: PK Column
A71: Releases | B71: Department | C71: → | D71: Reference Data | E71: Dept Code
A72: Releases | B72: Application | C72: → | D72: Applications | E72: Application Name
A73: Releases | B73: Release Owner ID | C73: → | D73: Users | E73: User ID
A74: Releases | B74: Stakeholder IDs | C74: → | D74: Users | E74: User ID (M:M)
A75: Applications | B75: Department | C75: → | D75: Reference Data | E75: Dept Code
A76: Env booking | B76: Release ID | C76: → | D76: Releases | E76: Release ID
A77: Env booking | B77: Application | C77: → | D77: Applications | E77: Application Name
A78: Risk | B78: Release ID | C78: → | D78: Releases | E78: Release ID
A79: Risk | B79: Risk Owner ID | C79: → | D79: Users | E79: User ID
A80: Drift | B80: Release ID | C80: → | D80: Releases | E80: Release ID
A81: Drift | B81: Application | C81: → | D81: Applications | E81: Application Name
... A94: Planned Maintenance | B94: Application | C94: → | D94: Applications | E94: Application Name
A98: SECTION 2: DETAILED SCHEMA DOCUMENTATION
A99: ═══════════════════════════════════════════════════════════════════════════════════════════════════════════════════
A101: Each sheet's schema is documented below with column definitions, data types, and validation rules.
A103: DATA TYPE LEGEND:
A104: • TEXT: Free-form text string
A105: • INT: Integer number
A106: • DATE: Date in YYYY-MM-DD format
A107: • DECIMAL: Number with decimal places
A108: • ENUM: Value from predefined list (see Reference Data sheet)
A109: • FK: Foreign key - must match value in referenced table
A110: • BOOL: Boolean (Yes/No or True/False)
A111: • ID: Auto-generated unique identifier
... A116: ───────────────────────────────────────────────────────────────────────────────────────────────────────────────────
A119: Column | B119: Header Name | C119: Data Type | D119: Required | E119: Validation/Constraints | F119: Description
...

Sheet Reference Data
A1: RELEASE DESK - REFERENCE DATA CATALOG
A2: Consolidated lookup tables, status codes, thresholds, and configuration data
A3: Version 1.0 | Generated: June 2026
A6: WORKBOOK STATISTICS
A7: Metric | B7: Value | C7: Source
A8: Total Departments | B8: 8 | C8: Applications sheet
A9: Total Applications | B9: 84 | C9: Applications sheet
A10: Total Releases | B10: 80 | C10: Releases sheet
A11: Total Users | B11: 100+ | C11: Users, Release Managers, Super Admins
A12: Risk Factors | B12: 44-46 | C12: Risk Factors sheet
A14: 1. DEPARTMENTS
A15: Dept ID | B15: Dept Code | C15: Dept Name | D15: Primary Focus
A16: DEPT-01 | B16: FIN | C16: Finance | D16: Financial planning, reporting, treasury
A17: DEPT-02 | B17: LOG | C17: Logistics | D17: Warehouse, transportation, supply chain
A18: DEPT-03 | B18: CRM | C18: CRM | D18: Sales, marketing, customer service
A19: DEPT-04 | B19: MFG | C19: Manufacturing | D19: Production, quality, MES systems
A20: DEPT-05 | B20: IT | C20: IT | D20: Infrastructure, monitoring, service desk
A21: DEPT-06 | B21: HR | C21: HR | D21: HCM, payroll, learning, talent
A22: DEPT-07 | B22: LEG | C22: Legal | D22: Contracts, compliance, document management
A23: DEPT-08 | B23: SEC | C23: Security | D23: Identity, access, threat detection
A26: 2. ENVIRONMENTS
A27: Env Code | B27: Env Name | C27: Promotion Order | D27: Availability | E27: Description
A28: DEV | B28: Development | C28: 1 | D28: 24/7 | E28: Developer sandbox environment
A29: TEST | B29: Testing | C29: 2 | D29: Business Hours | E29: QA and integration testing
A30: UAT | B30: User Acceptance | C30: 3 | D30: Business Hours | E30: Business validation environment
A31: PREPROD | B31: Pre-Production | C31: 4 | D31: Business Hours | E31: Production mirror for final validation
A32: PROD | B32: Production | C32: 5 | D32: 24/7 | E32: Live production environment
A33: DR | B33: Disaster Recovery | C33: 6 | D33: 24/7 | E33: Business continuity failover
A36: 3. RELEASE SIZES
A37: Size | B37: Test Days | C37: UAT Days | D37: Pre-Prod Days | E37: Total Lead Time | F37: Examples
A38: Small | B38: 3 | C38: 2 | D38: 1 | E38: ~8 days | F38: Bug fixes, minor UI changes
A39: Medium | B39: 5 | C39: 3 | D39: 2 | E39: ~12 days | F39: Feature enhancements, integrations
A40: Large | B40: 10 | C40: 5 | D40: 4 | E40: ~22 days | F40: Major releases, platform upgrades
A42: 4. IMPACT LEVELS
A43: Level | B43: Code | C43: Color | D43: Description | E43: Examples
A44: High | B44: H | C44: #FF0000 | D44: Critical business impact | E44: Core ERP, Payment Systems
A45: Medium | B45: M | C45: #FFC000 | D45: Moderate impact, workarounds exist | E45: Reporting, Secondary CRM
A46: Low | B46: L | C46: #00B050 | D46: Minimal impact, easily recoverable | E46: UI changes, Minor enhancements
A48: 5. PRIORITY LEVELS
A49: Priority | B49: Code | C49: Response Time | D49: Escalation | E49: Description
...

Sheet Applications
A1: Department | B1: Application | C1: Env | D1: Application Owner | E1: Tech Lead | F1: Env Owner
A2: Finance | B2: SAP S/4HANA Finance (FICO) | C2: Dev | D2: Sarah Mitchell | E2: James Wilson | F2: Alex Rivera (Dev Mgr)
B3: SAP S/4HANA Finance (FICO) | C3: Test | F3: Sam Anderson (QA Lead)
B4: SAP S/4HANA Finance (FICO) | C4: UAT | F4: Rachel Green (Bus Analyst)
B5: SAP S/4HANA Finance (FICO) | C5: Pre-prod | F5: Nathan Cole (Release Mgr)
B6: SAP S/4HANA Finance (FICO) | C6: Prod | F6: Victoria Sterling (Ops Mgr)
B7: SAP S/4HANA Finance (FICO) | C7: DR | F7: Robert Shield (Infra Lead)
B8: Anaplan | C8: Dev | D8: David Chen | E8: Emily Zhang | F8: Jordan Lee (Dev Mgr)
B9: Anaplan | C9: Test | F9: Chris Park (QA Lead)
B10: Anaplan | C10: UAT | F10: Monica Geller (Bus Analyst)
B11: Anaplan | C11: Pre-prod | F11: Ethan Black (Release Mgr)
B12: Anaplan | C12: Prod | F12: Elizabeth Crown (Ops Mgr)
B13: Anaplan | C13: DR | F13: William Guard (Infra Lead)
B14: Oracle Hyperion HFM | C14: Dev | D14: Jennifer Walsh | E14: Michael Brown | F14: Casey Chen (Dev Mgr)
B15: Oracle Hyperion HFM | C15: Test | F15: Pat Murphy (QA Lead)
B16: Oracle Hyperion HFM | C16: UAT | F16: Phoebe Buffay (Bus Analyst)
B17: Oracle Hyperion HFM | C17: Pre-prod | F17: Lucas White (Release Mgr)
B18: Oracle Hyperion HFM | C18: Prod | F18: Catherine Royal (Ops Mgr)
B19: Oracle Hyperion HFM | C19: DR | F19: James Fortress (Infra Lead)
B20: Kyriba | C20: Dev | D20: Robert Kim | E20: Priya Sharma | F20: Morgan Taylor (Dev Mgr)
B21: Kyriba | C21: Test | F21: Jesse Garcia (QA Lead)
B22: Kyriba | C22: UAT | F22: Emma Watson (Bus Analyst)
B23: Kyriba | C23: Pre-prod | F23: Mason Gray (Release Mgr)
B24: Kyriba | C24: Prod | F24: Margaret Noble (Ops Mgr)
B25: Kyriba | C25: DR | F25: Michael Bastion (Infra Lead)
B26: Coupa | C26: Dev | D26: Michelle Torres | E26: Christopher Davis | F26: Jamie Patel (Dev Mgr)
B27: Coupa | C27: Test | F27: Robin Chen (QA Lead)
B28: Coupa | C28: UAT | F28: Sophie Turner (Bus Analyst)
B29: Coupa | C29: Pre-prod | F29: Logan Stone (Release Mgr)
B30: Coupa | C30: Prod | F30: Diana Prince (Ops Mgr)
B31: Coupa | C31: DR | F31: David Tower (Infra Lead)
B32: Zuora | C32: Dev | D32: Andrew Patel | E32: Angela Liu | F32: Riley Kim (Dev Mgr)
B33: Zuora | C33: Test | F33: Dana Wilson (QA Lead)
B34: Zuora | C34: UAT | F34: Mia Collins (Bus Analyst)
B35: Zuora | C35: Pre-prod | F35: Jacob Hill (Release Mgr)
B36: Zuora | C36: Prod | F36: Helena Troy (Ops Mgr)
B37: Zuora | C37: DR | F37: Richard Wall (Infra Lead)
B38: RevPro | C38: Dev | D38: Lisa Thompson | E38: Daniel Park | F38: Quinn Johnson (Dev Mgr)
B39: RevPro | C39: Test | F39: Kelly Nguyen (QA Lead)
B40: RevPro | C40: UAT | F40: Isabella Moore (Bus Analyst)
...

Sheet Users
A1: User ID | B1: Name | C1: Email | D1: Role | E1: Department | F1: Manager | G1: Access Level | H1: Status | I1: Last Login
A2: USR-001 | B2: Alex Rivera | C2: alex.rivera@company.com | D2: Development Manager | E2: IT | F2: CTO Office | G2: Admin | H2: Active | I2: 46198
A3: USR-002 | B3: Jordan Lee | C3: jordan.lee@company.com | D3: Development Manager | E3: IT | F3: CTO Office | G3: Admin | H3: Active | I3: 46198
A4: USR-003 | B4: Casey Chen | C4: casey.chen@company.com | D4: Development Manager | E4: IT | F4: CTO Office | G4: Admin | H4: Active | I4: 46197
A5: USR-004 | B5: Morgan Taylor | C5: morgan.taylor@company.com | D5: Development Manager | E5: IT | F5: CTO Office | G5: Admin | H5: Active | I5: 46198
A6: USR-005 | B6: Jamie Patel | C6: jamie.patel@company.com | D6: Development Manager | E6: IT | F6: CTO Office | G6: Admin | H6: Active | I6: 46197
A7: USR-006 | B7: Riley Kim | C7: riley.kim@company.com | D7: Development Manager | E7: IT | F7: CTO Office | G7: Admin | H7: Active | I7: 46198
A8: USR-007 | B8: Quinn Johnson | C8: quinn.johnson@company.com | D8: Development Manager | E8: IT | F8: CTO Office | G8: Admin | H8: Active | I8: 46196
A9: USR-008 | B9: Avery Williams | C9: avery.williams@company.com | D9: Development Manager | E9: IT | F9: CTO Office | G9: Admin | H9: Active | I9: 46198
A10: USR-009 | B10: Drew Martinez | C10: drew.martinez@company.com | D10: Development Manager | E10: IT | F10: CTO Office | G10: Admin | H10: Active | I10: 46197
A11: USR-010 | B11: Cameron Brown | C11: cameron.brown@company.com | D11: Development Manager | E11: IT | F11: CTO Office | G11: Admin | H11: Active | I11: 46198
A12: USR-011 | B12: Taylor Singh | C12: taylor.singh@company.com | D12: Development Manager | E12: IT | F12: CTO Office | G12: Admin | H12: Active | I12: 46195
A13: USR-012 | B13: Blake Thompson | C13: blake.thompson@company.com | D13: Development Manager | E13: IT | F13: CTO Office | G13: Admin | H13: Active | I13: 46198
... A101: USR-100 | B101: Michelle Davis | C101: michelle.davis@company.com | D101: Project Manager | E101: PMO | F101: PMO Director | G101: Standard | H101: Active | I101: 46198

Sheet Admin (Release Managers)
A1: ID | B1: Name | C1: Email | D1: Department | E1: Region | F1: Phone | G1: Status | H1: Start Date | I1: Specialization
A2: RM-001 | B2: Nathan Cole | C2: nathan.cole@company.com | D2: IT | E2: North America | F2: +1-555-0101 | G2: Active | H2: 43905 | I2: Finance & HR Systems
A3: RM-002 | B3: Ethan Black | C3: ethan.black@company.com | D3: IT | E3: North America | F3: +1-555-0102 | G3: Active | H3: 43636 | I3: Manufacturing & Logistics
A4: RM-003 | B4: Lucas White | C4: lucas.white@company.com | D4: IT | E4: EMEA | F4: +44-20-5550103 | G4: Active | H4: 44206 | I4: CRM & Sales Systems
A5: RM-004 | B5: Mason Gray | C5: mason.gray@company.com | D5: IT | E5: EMEA | F5: +44-20-5550104 | G5: Active | H5: 43344 | I5: Security & Infrastructure
A6: RM-005 | B6: Logan Stone | C6: logan.stone@company.com | D6: IT | E6: APAC | F6: +61-2-5550105 | G6: Active | H6: 44150 | I6: Legal & Compliance
A7: RM-006 | B7: Jacob Hill | C7: jacob.hill@company.com | D7: IT | E7: APAC | F7: +61-2-5550106 | G7: Active | H7: 44620 | I7: HR & Talent Systems
A8: RM-007 | B8: Aiden Clark | C8: aiden.clark@company.com | D8: IT | E8: North America | F8: +1-555-0107 | G8: Active | H8: 43567 | I8: Integration & Middleware
A9: RM-008 | B9: Jackson Moore | C9: jackson.moore@company.com | D9: IT | E9: EMEA | F9: +44-20-5550108 | G9: Active | H9: 44399 | I9: Data & Analytics
A10: RM-009 | B10: Sebastian Hall | C10: sebastian.hall@company.com | D10: IT | E10: LATAM | F10: +55-11-5550109 | G10: Active | H10: 44048 | I10: ERP Systems
A11: RM-010 | B11: Caleb Young | C11: caleb.young@company.com | D11: IT | E11: North America | F11: +1-555-0110 | G11: Active | H11: 43070 | I11: Cloud & SaaS Platforms
A12: RM-011 | B12: Owen King | C12: owen.king@company.com | D12: IT | E12: APAC | F12: +65-5550111 | G12: Active | H12: 44699 | I12: Manufacturing Execution
A13: RM-012 | B13: Liam Wright | C13: liam.wright@company.com | D13: IT | E13: EMEA | F13: +49-30-5550112 | G13: On Leave | H13: 43768 | I13: Finance Reporting

Sheet Super Admins
A1: Admin ID | B1: Name | C1: Email | D1: Title | E1: Department | F1: Access Scope | G1: Granted Date | H1: Granted By | I1: Status | J1: Expiry Date | K1: Notes
A2: SA-001 | B2: Michael Stevens | C2: michael.stevens@company.com | D2: Chief Information Officer | E2: IT | F2: Global - All Systems | G2: 44635 | H2: CEO Office | I2: Active | J2: 46461 | K2: Executive sponsor for all IT initiatives
A3: SA-002 | B3: Jennifer Walsh | C3: jennifer.walsh@company.com | D3: VP of Enterprise Applications | E3: IT | F3: Global - All Systems | G3: 44936 | H3: Michael Stevens | I3: Active | J3: 46397 | K3: Oversight of all enterprise systems
A4: SA-003 | B4: Christopher Blake | C4: christopher.blake@company.com | D4: Director of IT Operations | E4: IT | F4: Global - Infrastructure | G4: 45097 | H4: Jennifer Walsh | I4: Active | J4: 46387 | K4: 24/7 operations oversight
A5: SA-004 | B5: Elizabeth Morgan | C5: elizabeth.morgan@company.com | D5: Head of Cybersecurity | E5: Security | F5: Global - All Systems | G5: 44774 | H5: Michael Stevens | I5: Active | J5: 46600 | K5: Security incident response authority
A6: SA-005 | B6: Robert Chen | C6: robert.chen@company.com | D6: Chief Technology Officer | E6: IT | F6: Global - All Systems | G6: 44326 | H6: CEO Office | I6: Active | J6: 46517 | K6: Technical architecture decisions
A7: SA-006 | B7: Patricia Wong | C7: patricia.wong@company.com | D7: Director of Release Management | E7: IT | F7: Global - Release Systems | G7: 45337 | H7: Jennifer Walsh | I7: Active | J7: 46249 | K7: Emergency release authority
A8: SA-007 | B8: Daniel Crawford | C8: daniel.crawford@company.com | D8: VP of HR Technology | E8: HR | F8: HR Systems - Global | G8: 45170 | H8: Jennifer Walsh | I8: Active | J8: 46266 | K8: HR data governance
A9: SA-008 | B9: Sarah Mitchell | C9: sarah.mitchell@company.com | D9: VP of Finance Systems | E9: Finance | F9: Finance Systems - Global | G9: 45031 | H9: Michael Stevens | I9: Active | J9: 46310 | K9: Financial data authority
A10: SA-009 | B10: Raymond Diaz | C10: raymond.diaz@company.com | D10: Cloud Platform Architect | E10: IT | F10: Global - Cloud Infrastructure | G10: 45296 | H10: Robert Chen | I10: Active | J10: 46208 | K10: AWS/Azure/GCP root access
A11: SA-010 | B11: Margaret Sullivan | C11: margaret.sullivan@company.com | D11: Identity & Access Manager | E11: Security | F11: Global - IAM Systems | G11: 45250 | H11: Elizabeth Morgan | I11: Active | J11: 46346 | K11: Identity management authority
A12: SA-011 | B12: Timothy Foster | C12: timothy.foster@company.com | D12: Disaster Recovery Manager | E12: IT | F12: Global - DR Systems | G12: 45361 | H12: Christopher Blake | I12: Active | J12: 46275 | K12: DR failover authority
A13: SA-012 | B13: Diane Wilson | C13: diane.wilson@company.com | D13: Database Administrator Lead | E13: IT | F13: Global - Databases | G13: 45122 | H13: Christopher Blake | I13: Active | J13: 46218 | K13: DBA root access all environments
A15: ⚠️ RESTRICTED ACCESS: Super Admin privileges require CIO or CEO approval. Access is audited and reviewed quarterly.

Sheet Releases
A1: 🔍 FILTERS
A2: Department: | B2: All | C2: Application: | D2: All | E2: Time Period: | F2: All Time | G2: Status: | H2: All | I2: Conflict: | J2: All
A3: Showing: | B3: =COUNTIF(AC5:AC84,TRUE)&" of "&COUNTA(A5:A84)&" releases" -> 80 of 80 releases | L3: 💡 Change filter values above to filter releases. Matching rows are highlighted in green; non-matching rows are greyed out.
A4: Release ID | B4: Release Name | C4: Department | D4: Application | E4: Dependencies | F4: Release Size | G4: Impact | H4: Priority | I4: CAB Date | J4: Start Date | K4: End Date | L4: Test Env Required | M4: UAT Env Required | N4: Status | O4: Conflict Flag | P4: Notes | Q4: Readiness % | R4: Blockers | S4: Vendor Maintenance | T4: Change Freeze | U4: Regulatory | V4: Release Owner ID | W4: Approval Status | X4: Depends On | Y4: Rollback Plan | Z4: Go-Live Checklist % | AA4: Stakeholder IDs | AB4: Deployment Window | AC4: Filter Match
A5: REL-0001 | B5: Kyriba UI Tweak v4.5 | C5: Finance | D5: Kyriba | E5: NA | F5: Small | G5: Low | H5: P4 - Low | I5: 46201 | J5: 46203 | K5: 46203 | L5: FIN-TEST-01 | M5: FIN-UAT-01 | N5: Blocked | O5: ⚠️ CONFLICT | P5: Resource conflict with REL-0003 - Same Test/UAT env required | Q5: 0.75 | R5: Environment conflict with REL-0003; awaiting conflict resolution meeting | T5: Quarter-End Freeze | V5: USR-061 | W5: On Hold | Y5: At Risk | Z5: 0.79 | AA5: USR-073,USR-085,USR-097 | AB5: Off-Peak | AC5: =AND( IF($B$2="All",TRUE,$C5=$B$2), IF($D$2="All",TRUE,$D5=$D$2), IF($H$2="All",TRUE,$N5=$H$2), IF($J$2="All",TRUE,IF($J$2="Has Conflict",$O5<>"",IF($J$2="No Conflict",$O5="",TRUE))), IF($F$2="All Time",TRUE,IF($F$2="Today",$J5=TODAY(),IF($F$2="This Week",AND($J5>=TODAY(),$J5<=TODAY()+7),IF($F$2="This Month",AND($J5>=TODAY(),$J5<=TODAY()+30),AND($J5>=DATE(YEAR(TODAY()),1,1),$J5<=DATE(YEAR(TODAY()),12,31)))))) ) -> TRUE
A6: REL-0002 | B6: Blue Workflow Automation v2.1 | C6: Logistics | D6: Blue Yonder WMS | E6: NA | F6: Medium | G6: High | H6: P1 - Critical | I6: 46205 | J6: 46207 | K6: 46208 | L6: LOG-TEST-01 | M6: LOG-UAT-01 | N6: Approved | P6: Executive sponsor: CFO | Q6: 0.95 | V6: USR-062 | W6: CAB Approved | Y6: Ready | Z6: 0.85 | AA6: USR-074,USR-086,USR-098 | AB6: Weekend | AC6: =AND( IF($B$2="All",TRUE,$C6=$B$2), IF($D$2="All",TRUE,$D6=$D$2), IF($H$2="All",TRUE,$N6=$H$2), IF($J$2="All",TRUE,IF($J$2="Has Conflict",$O6<>"",IF($J$2="No Conflict",$O6="",TRUE))), IF($F$2="All Time",TRUE,IF($F$2="Today",$J6=TODAY(),IF($F$2="This Week",AND($J6>=TODAY(),$J6<=TODAY()+7),IF($F$2="This Month",AND($J6>=TODAY(),$J6<=TODAY()+30),AND($J6>=DATE(YEAR(TODAY()),1,1),$J6<=DATE(YEAR(TODAY()),12,31)))))) ) -> TRUE
A7: REL-0003 | B7: Zendesk Minor Update v4.3 | C7: CRM | D7: Zendesk | E7: NA | F7: Small | G7: Low | H7: P3 - Medium | I7: 46203 | J7: 46205 | K7: 46205 | L7: FIN-TEST-01 | M7: FIN-UAT-01 | N7: Approved | O7: ⚠️ CONFLICT | P7: Resource conflict with REL-0007 - Same Test/UAT env required | Q7: 0.7 | R7: Shared UAT env with REL-0001; QA sign-off pending | V7: USR-063 | W7: CAB Approved | Y7: Ready | Z7: 0.91 | AA7: USR-075,USR-087,USR-097 | AB7: Business Hours | AC7: =AND( IF($B$2="All",TRUE,$C7=$B$2), IF($D$2="All",TRUE,$D7=$D$2), IF($H$2="All",TRUE,$N7=$H$2), IF($J$2="All",TRUE,IF($J$2="Has Conflict",$O7<>"",IF($J$2="No Conflict",$O7="",TRUE))), IF($F$2="All Time",TRUE,IF($F$2="Today",$J7=TODAY(),IF($F$2="This Week",AND($J7>=TODAY(),$J7<=TODAY()+7),IF($F$2="This Month",AND($J7>=TODAY(),$J7<=TODAY()+30),AND($J7>=DATE(YEAR(TODAY()),1,1),$J7<=DATE(YEAR(TODAY()),12,31)))))) ) -> TRUE
A8: REL-0004 | B8: AVEVA Dashboard Upgrade v5.5 | C8: Manufacturing | D8: AVEVA MES | E8: NA | F8: Medium | G8: High | H8: P1 - Critical | I8: 46213 | J8: 46215 | K8: 46216 | L8: MAN-TEST-03 | M8: MAN-UAT-01 | N8: Pending CAB | P8: Blackout period consideration | Q8: 0.88 | V8: USR-064 | W8: CAB Submitted | Y8: In Progress | Z8: 0.78 | AA8: USR-076,USR-088,USR-098 | AB8: Weekend | AC8: =AND( IF($B$2="All",TRUE,$C8=$B$2), IF($D$2="All",TRUE,$D8=$D$2), IF($H$2="All",TRUE,$N8=$H$2), IF($J$2="All",TRUE,IF($J$2="Has Conflict",$O8<>"",IF($J$2="No Conflict",$O8="",TRUE))), IF($F$2="All Time",TRUE,IF($F$2="Today",$J8=TODAY(),IF($F$2="This Week",AND($J8>=TODAY(),$J8<=TODAY()+7),IF($F$2="This Month",AND($J8>=TODAY(),$J8<=TODAY()+30),AND($J8>=DATE(YEAR(TODAY()),1,1),$J8<=DATE(YEAR(TODAY()),12,31)))))) ) -> TRUE
A9: REL-0005 | B9: Datadog Security Patch Bundle v3.5 | C9: IT | D9: Datadog | E9: NA | F9: Medium | G9: High | H9: P2 - High | I9: 46217 | J9: 46219 | K9: 46220 | L9: IT-TEST-01 | M9: IT-UAT-01 | N9: Testing | O9: ⚠️ CONFLICT | P9: Resource conflict with REL-0010 - Same Test/UAT env required | Q9: 0.8 | R9: Security review in progress; awaiting CISO approval | V9: USR-065 | W9: Testing | Y9: In Progress | Z9: 0.52 | AA9: USR-077,USR-089,USR-097 | AB9: Off-Peak | AC9: =AND( IF($B$2="All",TRUE,$C9=$B$2), IF($D$2="All",TRUE,$D9=$D$2), IF($H$2="All",TRUE,$N9=$H$2), IF($J$2="All",TRUE,IF($J$2="Has Conflict",$O9<>"",IF($J$2="No Conflict",$O9="",TRUE))), IF($F$2="All Time",TRUE,IF($F$2="Today",$J9=TODAY(),IF($F$2="This Week",AND($J9>=TODAY(),$J9<=TODAY()+7),IF($F$2="This Month",AND($J9>=TODAY(),$J9<=TODAY()+30),AND($J9>=DATE(YEAR(TODAY()),1,1),$J9<=DATE(YEAR(TODAY()),12,31)))))) ) -> TRUE
A10: REL-0006 | B10: SAP Configuration Change v5.2 | C10: HR | D10: SAP SuccessFactors | E10: NA | F10: Small | G10: Medium | H10: P2 - High | I10: 46221 | J10: 46223 | K10: 46223 | L10: HR-TEST-01 | M10: HR-UAT-01 | N10: Testing | P10: Integration testing with downstream systems | Q10: 0.82 | V10: USR-066 | W10: Testing | Y10: In Progress | Z10: 0.64 | AA10: USR-078,USR-090,USR-098 | AB10: Business Hours | AC10: =AND( IF($B$2="All",TRUE,$C10=$B$2), IF($D$2="All",TRUE,$D10=$D$2), IF($H$2="All",TRUE,$N10=$H$2), IF($J$2="All",TRUE,IF($J$2="Has Conflict",$O10<>"",IF($J$2="No Conflict",$O10="",TRUE))), IF($F$2="All Time",TRUE,IF($F$2="Today",$J10=TODAY(),IF($F$2="This Week",AND($J10>=TODAY(),$J10<=TODAY()+7),IF($F$2="This Month",AND($J10>=TODAY(),$J10<=TODAY()+30),AND($J10>=DATE(YEAR(TODAY()),1,1),$J10<=DATE(YEAR(TODAY()),12,31)))))) ) -> TRUE
A11: REL-0007 | B11: Mitratech Integration Enhancement v5.2 | C11: Legal | D11: Mitratech TeamConnect | E11: NA | F11: Medium | G11: High | H11: P2 - High | I11: 46205 | J11: 46207 | K11: 46208 | L11: FIN-TEST-01 | M11: FIN-UAT-01 | N11: Approved | O11: ⚠️ CONFLICT | P11: Resource conflict with REL-0012 - Same Test/UAT env required | Q11: 0.65 | R11: Integration testing delayed; 3rd party API dependency unresolved | V11: USR-067 | W11: CAB Approved | Y11: Ready | Z11: 0.88 | AA11: USR-079,USR-091,USR-097 | AB11: Weekend | AC11: =AND( IF($B$2="All",TRUE,$C11=$B$2), IF($D$2="All",TRUE,$D11=$D$2), IF($H$2="All",TRUE,$N11=$H$2), IF($J$2="All",TRUE,IF($J$2="Has Conflict",$O11<>"",IF($J$2="No Conflict",$O11="",TRUE))), IF($F$2="All Time",TRUE,IF($F$2="Today",$J11=TODAY(),IF($F$2="This Week",AND($J11>=TODAY(),$J11<=TODAY()+7),IF($F$2="This Month",AND($J11>=TODAY(),$J11<=TODAY()+30),AND($J11>=DATE(YEAR(TODAY()),1,1),$J11<=DATE(YEAR(TODAY()),12,31)))))) ) -> TRUE
A12: REL-0008 | B12: CrowdStrike Minor Update v3.6 | C12: Security | D12: CrowdStrike Falcon | E12: NA | F12: Small | G12: Low | H12: P3 - Medium | I12: 46232 | J12: 46234 | K12: 46234 | L12: SEC-TEST-01 | M12: SEC-UAT-02 | N12: Planning | P12: Data migration included | Q12: 0.7 | V12: USR-068 | W12: Planning | Y12: Not Started | Z12: 0.26 | AA12: USR-080,USR-092,USR-098 | AB12: Off-Peak | AC12: =AND( IF($B$2="All",TRUE,$C12=$B$2), IF($D$2="All",TRUE,$D12=$D$2), IF($H$2="All",TRUE,$N12=$H$2), IF($J$2="All",TRUE,IF($J$2="Has Conflict",$O12<>"",IF($J$2="No Conflict",$O12="",TRUE))), IF($F$2="All Time",TRUE,IF($F$2="Today",$J12=TODAY(),IF($F$2="This Week",AND($J12>=TODAY(),$J12<=TODAY()+7),IF($F$2="This Month",AND($J12>=TODAY(),$J12<=TODAY()+30),AND($J12>=DATE(YEAR(TODAY()),1,1),$J12<=DATE(YEAR(TODAY()),12,31)))))) ) -> TRUE
A13: REL-0009 | B13: Oracle Report Fix v3.4 | C13: Finance | D13: Oracle Hyperion HFM | E13: {=IFERROR(_xlfn.TEXTJOIN(CHAR(10),TRUE,_xlfn._xlws.FILTER(#REF!&": "&#REF!,#REF!=$A13,"")),"")} | F13: Small | G13: Medium | H13: P2 - High | I13: 46236 | J13: 46238 | K13: 46238 | L13: FIN-TEST-03 | M13: FIN-UAT-01 | N13: Planning | O13: ⚠️ CONFLICT | P13: Resource conflict with REL-0014 - Same Test/UAT env required | Q13: 0.55 | R13: UAT defects being triaged; 2 P2 bugs outstanding | V13: USR-001 | W13: Planning | X13: REL-0007 | Y13: Not Started | Z13: 0.27 | AA13: USR-073,USR-085,USR-097 | AB13: Business Hours | AC13: =AND( IF($B$2="All",TRUE,$C13=$B$2), IF($D$2="All",TRUE,$D13=$D$2), IF($H$2="All",TRUE,$N13=$H$2), IF($J$2="All",TRUE,IF($J$2="Has Conflict",$O13<>"",IF($J$2="No Conflict",$O13="",TRUE))), IF($F$2="All Time",TRUE,IF($F$2="Today",$J13=TODAY(),IF($F$2="This Week",AND($J13>=TODAY(),$J13<=TODAY()+7),IF($F$2="This Month",AND($J13>=TODAY(),$J13<=TODAY()+30),AND($J13>=DATE(YEAR(TODAY()),1,1),$J13<=DATE(YEAR(TODAY()),12,31)))))) ) -> TRUE
A14: REL-0010 | B14: Manhattan Major Enhancement v5.2 | C14: Logistics | D14: Manhattan Associates WMS | E14: NA | F14: Large | G14: Medium | H14: P2 - High | I14: 46218 | J14: 46221 | K14: 46223 | L14: IT-TEST-01 | M14: IT-UAT-01 | N14: Testing | O14: ⚠️ CONFLICT | P14: Resource conflict with REL-0005 - Same Test/UAT env required | Q14: 0.6 | R14: Performance testing incomplete; DB migration script needs optimization | V14: USR-002 | W14: Testing | Y14: In Progress | Z14: 0.64 | AA14: USR-074,USR-086,USR-098 | AB14: Weekend | AC14: =AND( IF($B$2="All",TRUE,$C14=$B$2), IF($D$2="All",TRUE,$D14=$D$2), IF($H$2="All",TRUE,$N14=$H$2), IF($J$2="All",TRUE,IF($J$2="Has Conflict",$O14<>"",IF($J$2="No Conflict",$O14="",TRUE))), IF($F$2="All Time",TRUE,IF($F$2="Today",$J14=TODAY(),IF($F$2="This Week",AND($J14>=TODAY(),$J14<=TODAY()+7),IF($F$2="This Month",AND($J14>=TODAY(),$J14<=TODAY()+30),AND($J14>=DATE(YEAR(TODAY()),1,1),$J14<=DATE(YEAR(TODAY()),12,31)))))) ) -> TRUE
A15: REL-0011 | B15: HubSpot Minor Update v3.7 | C15: CRM | D15: HubSpot CRM | E15: NA | F15: Small | G15: Low | H15: P3 - Medium | I15: 46244 | J15: 46246 | K15: 46246 | L15: CRM-TEST-02 | M15: CRM-UAT-01 | N15: Planning | O15: ⚠️ CONFLICT | P15: Resource conflict with REL-0014 - Same Test/UAT env required | Q15: 0.4 | V15: USR-003 | W15: Planning | Y15: Not Started | Z15: 0.29 | AA15: USR-075,USR-087,USR-097 | AB15: Business Hours | AC15: =AND( IF($B$2="All",TRUE,$C15=$B$2), IF($D$2="All",TRUE,$D15=$D$2), IF($H$2="All",TRUE,$N15=$H$2), IF($J$2="All",TRUE,IF($J$2="Has Conflict",$O15<>"",IF($J$2="No Conflict",$O15="",TRUE))), IF($F$2="All Time",TRUE,IF($F$2="Today",$J15=TODAY(),IF($F$2="This Week",AND($J15>=TODAY(),$J15<=TODAY()+7),IF($F$2="This Month",AND($J15>=TODAY(),$J15<=TODAY()+30),AND($J15>=DATE(YEAR(TODAY()),1,1),$J15<=DATE(YEAR(TODAY()),12,31)))))) ) -> TRUE
A16: REL-0012 | B16: Plex Report Fix v2.5 | C16: Manufacturing | D16: Plex Smart Manufacturing | E16: NA | F16: Small | G16: Medium | H16: P3 - Medium | I16: 46207 | J16: 46209 | K16: 46209 | L16: FIN-TEST-01 | M16: FIN-UAT-01 | N16: Approved | O16: ⚠️ CONFLICT | P16: Resource conflict with REL-0007 - Same Test/UAT env required | Q16: 0.72 | R16: Test data refresh pending; blocked on DBA availability | V16: USR-004 | W16: CAB Approved | Y16: Ready | Z16: 0.89 | AA16: USR-076,USR-088,USR-098 | AB16: Off-Peak | AC16: =AND( IF($B$2="All",TRUE,$C16=$B$2), IF($D$2="All",TRUE,$D16=$D$2), IF($H$2="All",TRUE,$N16=$H$2), IF($J$2="All",TRUE,IF($J$2="Has Conflict",$O16<>"",IF($J$2="No Conflict",$O16="",TRUE))), IF($F$2="All Time",TRUE,IF($F$2="Today",$J16=TODAY(),IF($F$2="This Week",AND($J16>=TODAY(),$J16<=TODAY()+7),IF($F$2="This Month",AND($J16>=TODAY(),$J16<=TODAY()+30),AND($J16>=DATE(YEAR(TODAY()),1,1),$J16<=DATE(YEAR(TODAY()),12,31)))))) ) -> TRUE
A17: REL-0013 | B17: Dynatrace UI Tweak v3.1 | C17: IT | D17: Dynatrace | E17: {=IFERROR(_xlfn.TEXTJOIN(CHAR(10),TRUE,_xlfn._xlws.FILTER(#REF!&": "&#REF!,#REF!=$A17,"")),"")} | F17: Small | G17: Low | H17: P3 - Medium | I17: 46252 | J17: 46254 | K17: 46254 | L17: IT-TEST-03 | M17: IT-UAT-01 | N17: Planning | O17: ⚠️ CONFLICT | P17: Resource conflict with REL-0015 - Same Test/UAT env required | Q17: 0.35 | V17: USR-005 | W17: Planning | X17: REL-0012 | Y17: Not Started | Z17: 0.49 | AA17: USR-077,USR-089,USR-097 | AB17: Business Hours | AC17: =AND( IF($B$2="All",TRUE,$C17=$B$2), IF($D$2="All",TRUE,$D17=$D$2), IF($H$2="All",TRUE,$N17=$H$2), IF($J$2="All",TRUE,IF($J$2="Has Conflict",$O17<>"",IF($J$2="No Conflict",$O17="",TRUE))), IF($F$2="All Time",TRUE,IF($F$2="Today",$J17=TODAY(),IF($F$2="This Week",AND($J17>=TODAY(),$J17<=TODAY()+7),IF($F$2="This Month",AND($J17>=TODAY(),$J17<=TODAY()+30),AND($J17>=DATE(YEAR(TODAY()),1,1),$J17<=DATE(YEAR(TODAY()),12,31)))))) ) -> TRUE
A18: REL-0014 | B18: Oracle Global Rollout v2.2 | C18: HR | D18: Oracle HCM Cloud | E18: NA | F18: Large | G18: High | H18: P2 - High | I18: 46245 | J18: 46248 | K18: 46250 | L18: CRM-TEST-02 | M18: CRM-UAT-01 | N18: Planning | O18: ⚠️ CONFLICT | P18: Resource conflict with REL-0011 - Same Test/UAT env required | Q18: 0.45 | R18: Global rollout coordination pending; APAC team capacity constrained | V18: USR-006 | W18: Planning | Y18: Not Started | Z18: 0.21 | AA18: USR-078,USR-090,USR-098 | AB18: Weekend | AC18: =AND( IF($B$2="All",TRUE,$C18=$B$2), IF($D$2="All",TRUE,$D18=$D$2), IF($H$2="All",TRUE,$N18=$H$2), IF($J$2="All",TRUE,IF($J$2="Has Conflict",$O18<>"",IF($J$2="No Conflict",$O18="",TRUE))), IF($F$2="All Time",TRUE,IF($F$2="Today",$J18=TODAY(),IF($F$2="This Week",AND($J18>=TODAY(),$J18<=TODAY()+7),IF($F$2="This Month",AND($J18>=TODAY(),$J18<=TODAY()+30),AND($J18>=DATE(YEAR(TODAY()),1,1),$J18<=DATE(YEAR(TODAY()),12,31)))))) ) -> TRUE
A19: REL-0015 | B19: DocuSign Core Transformation v1.0 | C19: Legal | D19: DocuSign CLM | E19: NA | F19: Large | G19: High | H19: P2 - High | I19: 46253 | J19: 46256 | K19: 46258 | L19: IT-TEST-03 | M19: IT-UAT-01 | N19: Planning | O19: ⚠️ CONFLICT | P19: Resource conflict with REL-0017 - Same Test/UAT env required | Q19: 0.38 | R19: Architecture review required; security scan findings need remediation | V19: USR-061 | W19: Planning | Y19: Not Started | Z19: 0.24 | AA19: USR-079,USR-091,USR-097 | AB19: Weekend | AC19: =AND( IF($B$2="All",TRUE,$C19=$B$2), IF($D$2="All",TRUE,$D19=$D$2), IF($H$2="All",TRUE,$N19=$H$2), IF($J$2="All",TRUE,IF($J$2="Has Conflict",$O19<>"",IF($J$2="No Conflict",$O19="",TRUE))), IF($F$2="All Time",TRUE,IF($F$2="Today",$J19=TODAY(),IF($F$2="This Week",AND($J19>=TODAY(),$J19<=TODAY()+7),IF($F$2="This Month",AND($J19>=TODAY(),$J19<=TODAY()+30),AND($J19>=DATE(YEAR(TODAY()),1,1),$J19<=DATE(YEAR(TODAY()),12,31)))))) ) -> TRUE
A20: REL-0016 | B20: CyberArk Enterprise Integration v2.0 | C20: Security | D20: CyberArk PAM | E20: NA | F20: Large | G20: High | H20: P2 - High | I20: 46266 | J20: 46269 | K20: 46271 | L20: SEC-TEST-01 | M20: SEC-UAT-02 | N20: Draft | P20: Change Advisory Board approval needed | U20: SOC2 Requirement | V20: USR-062 | W20: Draft | Y20: Not Started | Z20: 0.07 | AA20: USR-080,USR-092,USR-098 | AB20: Weekend | AC20: =AND( IF($B$2="All",TRUE,$C20=$B$2), IF($D$2="All",TRUE,$D20=$D$2), IF($H$2="All",TRUE,$N20=$H$2), IF($J$2="All",TRUE,IF($J$2="Has Conflict",$O20<>"",IF($J$2="No Conflict",$O20="",TRUE))), IF($F$2="All Time",TRUE,IF($F$2="Today",$J20=TODAY(),IF($F$2="This Week",AND($J20>=TODAY(),$J20<=TODAY()+7),IF($F$2="This Month",AND($J20>=TODAY(),$J20<=TODAY()+30),AND($J20>=DATE(YEAR(TODAY()),1,1),$J20<=DATE(YEAR(TODAY()),12,31)))))) ) -> TRUE
A21: REL-0017 | B21: HighRadius Report Fix v2.4 | C21: Finance | D21: HighRadius | E21: {=IFERROR(_xlfn.TEXTJOIN(CHAR(10),TRUE,_xlfn._xlws.FILTER(#REF!&": "&#REF!,#REF!=$A21,"")),"")} | F21: Small | G21: Low | H21: P3 - Medium | I21: 46256 | J21: 46258 | K21: 46258 | L21: IT-TEST-03 | M21: IT-UAT-01 | N21: Planning | O21: ⚠️ CONFLICT | P21: Resource conflict with REL-0022 - Same Test/UAT env required | Q21: 0.3 | V21: USR-063 | W21: Planning | X21: REL-0014,REL-0012 | Y21: Not Started | Z21: 0.35 | AA21: USR-073,USR-085,USR-097 | AB21: Off-Peak | AC21: =AND( IF($B$2="All",TRUE,$C21=$B$2), IF($D$2="All",TRUE,$D21=$D$2), IF($H$2="All",TRUE,$N21=$H$2), IF($J$2="All",TRUE,IF($J$2="Has Conflict",$O21<>"",IF($J$2="No Conflict",$O21="",TRUE))), IF($F$2="All Time",TRUE,IF($F$2="Today",$J21=TODAY(),IF($F$2="This Week",AND($J21>=TODAY(),$J21<=TODAY()+7),IF($F$2="This Month",AND($J21>=TODAY(),$J21<=TODAY()+30),AND($J21>=DATE(YEAR(TODAY()),1,1),$J21<=DATE(YEAR(TODAY()),12,31)))))) ) -> TRUE
